Workbook

Sheet Analysis
C1: count
B2: Enrollment | C2: 184 | D2: separate source
B3: Building | C3: 638 | D3: Main | E3: 507 | F3: after removing 0 and NULL and duplicates.
B4: Distance | C4: 507
B5: Sector | C5: 354

Sheet Enrollment
A1: building | B1: present in building | C1: present in distance | D1: present in sector
A2: BALLANTINE HALL | B2: =VLOOKUP(A2,Building!A:A,1,FALSE) -> BALLANTINE HALL | C2: =VLOOKUP(A2,Distance!A:A,1,FALSE) -> BALLANTINE HALL | D2: =VLOOKUP(A2,Sector!A:A,1,FALSE) -> #N/A
A3: BLDG NOT ASSIGNED | B3: =VLOOKUP(A3,Building!A:A,1,FALSE) -> #N/A | C3: =VLOOKUP(A3,Distance!A:A,1,FALSE) -> #N/A | D3: =VLOOKUP(A3,Sector!A:A,1,FALSE) -> #N/A
A4: FRANKLIN HALL | B4: =VLOOKUP(A4,Building!A:A,1,FALSE) -> FRANKLIN HALL | C4: =VLOOKUP(A4,Distance!A:A,1,FALSE) -> FRANKLIN HALL | D4: =VLOOKUP(A4,Sector!A:A,1,FALSE) -> FRANKLIN HALL
A5: GLOBAL & INTL STUDIES BLDG | B5: =VLOOKUP(A5,Building!A:A,1,FALSE) -> GLOBAL & INTL STUDIES BLDG | C5: =VLOOKUP(A5,Distance!A:A,1,FALSE) -> GLOBAL & INTL STUDIES BLDG | D5: =VLOOKUP(A5,Sector!A:A,1,FALSE) -> GLOBAL & INTL STUDIES BLDG
A6: HEALTH INFO AND TRANSLATIONAL | B6: =VLOOKUP(A6,Building!A:A,1,FALSE) -> #N/A | C6: =VLOOKUP(A6,Distance!A:A,1,FALSE) -> #N/A | D6: =VLOOKUP(A6,Sector!A:A,1,FALSE) -> #N/A
A7: HODGE HALL (BUSINESS SCHOOL) | B7: =VLOOKUP(A7,Building!A:A,1,FALSE) -> HODGE HALL (BUSINESS SCHOOL) | C7: =VLOOKUP(A7,Distance!A:A,1,FALSE) -> HODGE HALL (BUSINESS SCHOOL) | D7: =VLOOKUP(A7,Sector!A:A,1,FALSE) -> HODGE HALL (BUSINESS SCHOOL)
A8: KIRKWOOD HALL | B8: =VLOOKUP(A8,Building!A:A,1,FALSE) -> KIRKWOOD HALL | C8: =VLOOKUP(A8,Distance!A:A,1,FALSE) -> KIRKWOOD HALL | D8: =VLOOKUP(A8,Sector!A:A,1,FALSE) -> KIRKWOOD HALL
A9: LEE NORVELLE THEATRE DRAMA/ NE | B9: =VLOOKUP(A9,Building!A:A,1,FALSE) -> #N/A | C9: =VLOOKUP(A9,Distance!A:A,1,FALSE) -> #N/A | D9: =VLOOKUP(A9,Sector!A:A,1,FALSE) -> #N/A
A10: LINDLEY HALL | B10: =VLOOKUP(A10,Building!A:A,1,FALSE) -> LINDLEY HALL | C10: =VLOOKUP(A10,Distance!A:A,1,FALSE) -> LINDLEY HALL | D10: =VLOOKUP(A10,Sector!A:A,1,FALSE) -> LINDLEY HALL
A11: LUDDY HALL (INFORMATICS) | B11: =VLOOKUP(A11,Building!A:A,1,FALSE) -> LUDDY HALL (INFORMATICS) | C11: =VLOOKUP(A11,Distance!A:A,1,FALSE) -> LUDDY HALL (INFORMATICS) | D11: =VLOOKUP(A11,Sector!A:A,1,FALSE) -> #N/A
A12: PSYCHOLOGY | B12: =VLOOKUP(A12,Building!A:A,1,FALSE) -> PSYCHOLOGY | C12: =VLOOKUP(A12,Distance!A:A,1,FALSE) -> PSYCHOLOGY | D12: =VLOOKUP(A12,Sector!A:A,1,FALSE) -> PSYCHOLOGY
A13: SCHOOL OF PUBLIC HEALTH | B13: =VLOOKUP(A13,Building!A:A,1,FALSE) -> SCHOOL OF PUBLIC HEALTH | C13: =VLOOKUP(A13,Distance!A:A,1,FALSE) -> SCHOOL OF PUBLIC HEALTH | D13: =VLOOKUP(A13,Sector!A:A,1,FALSE) -> #N/A
... A184: MAXWELL HALL | B184: =VLOOKUP(A184,Building!A:A,1,FALSE) -> MAXWELL HALL | C184: =VLOOKUP(A184,Distance!A:A,1,FALSE) -> MAXWELL HALL | D184: =VLOOKUP(A184,Sector!A:A,1,FALSE) -> MAXWELL HALL

Sheet Building
A1: FACIL_BLDG_DESC | B1: present in enrollment | C1: present in distance | D1: present in sector | E1: present in new sector
A2: SITE | B2: =VLOOKUP(A2,Enrollment!A:A,1,FALSE) -> #N/A | C2: =VLOOKUP(A2,Distance!A:A,1,FALSE) -> SITE | D2: =VLOOKUP(A2,Sector!A:A,1,FALSE) -> #N/A | E2: =VLOOKUP(A2,'new Sector'!A:A,1,0) -> #N/A
A3: LOWELL E. BAIER HALL | B3: =VLOOKUP(A3,Enrollment!A:A,1,FALSE) -> LOWELL E. BAIER HALL | C3: =VLOOKUP(A3,Distance!A:A,1,FALSE) -> LOWELL E. BAIER HALL | D3: =VLOOKUP(A3,Sector!A:A,1,FALSE) -> LOWELL E. BAIER HALL | E3: =VLOOKUP(A3,'new Sector'!A:A,1,0) -> LOWELL E. BAIER HALL
A4: 4TH & INDIANA-LEWIS BLDG | B4: =VLOOKUP(A4,Enrollment!A:A,1,FALSE) -> 4TH & INDIANA-LEWIS BLDG | C4: =VLOOKUP(A4,Distance!A:A,1,FALSE) -> 4TH & INDIANA-LEWIS BLDG | D4: =VLOOKUP(A4,Sector!A:A,1,FALSE) -> 4TH & INDIANA-LEWIS BLDG | E4: =VLOOKUP(A4,'new Sector'!A:A,1,0) -> 4TH & INDIANA-LEWIS BLDG
A5: 502 E 4TH ST | B5: =VLOOKUP(A5,Enrollment!A:A,1,FALSE) -> #N/A | C5: =VLOOKUP(A5,Distance!A:A,1,FALSE) -> 502 E 4TH ST | D5: =VLOOKUP(A5,Sector!A:A,1,FALSE) -> 502 E 4TH ST | E5: =VLOOKUP(A5,'new Sector'!A:A,1,0) -> 502 E 4TH ST
A6: BRYAN HALL | B6: =VLOOKUP(A6,Enrollment!A:A,1,FALSE) -> #N/A | C6: =VLOOKUP(A6,Distance!A:A,1,FALSE) -> BRYAN HALL | D6: =VLOOKUP(A6,Sector!A:A,1,FALSE) -> BRYAN HALL | E6: =VLOOKUP(A6,'new Sector'!A:A,1,0) -> BRYAN HALL
A7: CARMICHAEL CENTER | B7: =VLOOKUP(A7,Enrollment!A:A,1,FALSE) -> #N/A | C7: =VLOOKUP(A7,Distance!A:A,1,FALSE) -> CARMICHAEL CENTER | D7: =VLOOKUP(A7,Sector!A:A,1,FALSE) -> CARMICHAEL CENTER | E7: =VLOOKUP(A7,'new Sector'!A:A,1,0) -> CARMICHAEL CENTER
A8: VON LEE | B8: =VLOOKUP(A8,Enrollment!A:A,1,FALSE) -> #N/A | C8: =VLOOKUP(A8,Distance!A:A,1,FALSE) -> VON LEE | D8: =VLOOKUP(A8,Sector!A:A,1,FALSE) -> VON LEE | E8: =VLOOKUP(A8,'new Sector'!A:A,1,0) -> VON LEE
A9: FRANKLIN HALL | B9: =VLOOKUP(A9,Enrollment!A:A,1,FALSE) -> FRANKLIN HALL | C9: =VLOOKUP(A9,Distance!A:A,1,FALSE) -> FRANKLIN HALL | D9: =VLOOKUP(A9,Sector!A:A,1,FALSE) -> FRANKLIN HALL | E9: =VLOOKUP(A9,'new Sector'!A:A,1,0) -> FRANKLIN HALL
A10: POPLARS PARKING | B10: =VLOOKUP(A10,Enrollment!A:A,1,FALSE) -> #N/A | C10: =VLOOKUP(A10,Distance!A:A,1,FALSE) -> POPLARS PARKING | D10: =VLOOKUP(A10,Sector!A:A,1,FALSE) -> POPLARS PARKING | E10: =VLOOKUP(A10,'new Sector'!A:A,1,0) -> POPLARS PARKING
A11: CTR REP GOVERNMENT | B11: =VLOOKUP(A11,Enrollment!A:A,1,FALSE) -> #N/A | C11: =VLOOKUP(A11,Distance!A:A,1,FALSE) -> CTR REP GOVERNMENT | D11: =VLOOKUP(A11,Sector!A:A,1,FALSE) -> CTR REP GOVERNMENT | E11: =VLOOKUP(A11,'new Sector'!A:A,1,0) -> CTR REP GOVERNMENT
A12: 214 N DUNN ST | B12: =VLOOKUP(A12,Enrollment!A:A,1,FALSE) -> #N/A | C12: =VLOOKUP(A12,Distance!A:A,1,FALSE) -> 214 N DUNN ST | D12: =VLOOKUP(A12,Sector!A:A,1,FALSE) -> 214 N DUNN ST | E12: =VLOOKUP(A12,'new Sector'!A:A,1,0) -> 214 N DUNN ST
A13: 222 N DUNN ST | B13: =VLOOKUP(A13,Enrollment!A:A,1,FALSE) -> #N/A | C13: =VLOOKUP(A13,Distance!A:A,1,FALSE) -> 222 N DUNN ST | D13: =VLOOKUP(A13,Sector!A:A,1,FALSE) -> 222 N DUNN ST | E13: =VLOOKUP(A13,'new Sector'!A:A,1,0) -> 222 N DUNN ST
... A507: FIELD HOCKEY PRESSBOX | B507: =VLOOKUP(A507,Enrollment!A:A,1,FALSE) -> #N/A | C507: =VLOOKUP(A507,Distance!A:A,1,FALSE) -> FIELD HOCKEY PRESSBOX | D507: =VLOOKUP(A507,Sector!A:A,1,FALSE) -> FIELD HOCKEY PRESSBOX | E507: =VLOOKUP(A507,'new Sector'!A:A,1,0) -> FIELD HOCKEY PRESSBOX

Sheet Distance
A1: Building | B1: present in enrollment | C1: present in building | D1: present in sector
A2: 1000 N INDIANA AVE | B2: =VLOOKUP(A2,Enrollment!A:A,1,FALSE) -> #N/A | C2: =VLOOKUP(A2,Building!A:A,1,FALSE) -> 1000 N INDIANA AVE | D2: =VLOOKUP(A2,Sector!A:A,1,FALSE) -> #N/A
A3: 1001 E SR 45 46 BYP | B3: =VLOOKUP(A3,Enrollment!A:A,1,FALSE) -> #N/A | C3: =VLOOKUP(A3,Building!A:A,1,FALSE) -> 1001 E SR 45 46 BYP | D3: =VLOOKUP(A3,Sector!A:A,1,FALSE) -> 1001 E SR 45 46 BYP
A4: 1015 E ATWATER AVE | B4: =VLOOKUP(A4,Enrollment!A:A,1,FALSE) -> #N/A | C4: =VLOOKUP(A4,Building!A:A,1,FALSE) -> 1015 E ATWATER AVE | D4: =VLOOKUP(A4,Sector!A:A,1,FALSE) -> 1015 E ATWATER AVE
A5: 102 S BRYAN AVE | B5: =VLOOKUP(A5,Enrollment!A:A,1,FALSE) -> #N/A | C5: =VLOOKUP(A5,Building!A:A,1,FALSE) -> 102 S BRYAN AVE | D5: =VLOOKUP(A5,Sector!A:A,1,FALSE) -> #N/A
A6: 1020 N INDIANA AVE | B6: =VLOOKUP(A6,Enrollment!A:A,1,FALSE) -> #N/A | C6: =VLOOKUP(A6,Building!A:A,1,FALSE) -> 1020 N INDIANA AVE | D6: =VLOOKUP(A6,Sector!A:A,1,FALSE) -> 1020 N INDIANA AVE
A7: 104 S BRYAN AVE | B7: =VLOOKUP(A7,Enrollment!A:A,1,FALSE) -> #N/A | C7: =VLOOKUP(A7,Building!A:A,1,FALSE) -> 104 S BRYAN AVE | D7: =VLOOKUP(A7,Sector!A:A,1,FALSE) -> #N/A
A8: 1103 E ATWATER AVE | B8: =VLOOKUP(A8,Enrollment!A:A,1,FALSE) -> #N/A | C8: =VLOOKUP(A8,Building!A:A,1,FALSE) -> 1103 E ATWATER AVE | D8: =VLOOKUP(A8,Sector!A:A,1,FALSE) -> 1103 E ATWATER AVE
A9: 1103 N FESS AVE | B9: =VLOOKUP(A9,Enrollment!A:A,1,FALSE) -> #N/A | C9: =VLOOKUP(A9,Building!A:A,1,FALSE) -> 1103 N FESS AVE | D9: =VLOOKUP(A9,Sector!A:A,1,FALSE) -> 1103 N FESS AVE
A10: 1104 N WOODLAWN AVE | B10: =VLOOKUP(A10,Enrollment!A:A,1,FALSE) -> #N/A | C10: =VLOOKUP(A10,Building!A:A,1,FALSE) -> 1104 N WOODLAWN AVE | D10: =VLOOKUP(A10,Sector!A:A,1,FALSE) -> #N/A
A11: 1105 E ATWATER AVE | B11: =VLOOKUP(A11,Enrollment!A:A,1,FALSE) -> #N/A | C11: =VLOOKUP(A11,Building!A:A,1,FALSE) -> 1105 E ATWATER AVE | D11: =VLOOKUP(A11,Sector!A:A,1,FALSE) -> 1105 E ATWATER AVE
A12: 1106 N WOODLAWN AVE | B12: =VLOOKUP(A12,Enrollment!A:A,1,FALSE) -> #N/A | C12: =VLOOKUP(A12,Building!A:A,1,FALSE) -> 1106 N WOODLAWN AVE | D12: =VLOOKUP(A12,Sector!A:A,1,FALSE) -> #N/A
A13: 111 N BRYAN AVE | B13: =VLOOKUP(A13,Enrollment!A:A,1,FALSE) -> #N/A | C13: =VLOOKUP(A13,Building!A:A,1,FALSE) -> 111 N BRYAN AVE | D13: =VLOOKUP(A13,Sector!A:A,1,FALSE) -> 111 N BRYAN AVE
... A507: ZETA TAU ALPHA | B507: =VLOOKUP(A507,Enrollment!A:A,1,FALSE) -> #N/A | C507: =VLOOKUP(A507,Building!A:A,1,FALSE) -> ZETA TAU ALPHA | D507: =VLOOKUP(A507,Sector!A:A,1,FALSE) -> ZETA TAU ALPHA

Sheet Sector
A1: Building | B1: present in enrollment | C1: present in building | D1: present in distance
A2: IU STUDENT HEALTH CENTER | B2: =VLOOKUP(A2,Enrollment!A:A,1,FALSE) -> #N/A | C2: =VLOOKUP(A2,Building!A:A,1,FALSE) -> IU STUDENT HEALTH CENTER | D2: =VLOOKUP(A2,Distance!A:A,1,FALSE) -> IU STUDENT HEALTH CENTER
A3: IU WAREHOUSE | B3: =VLOOKUP(A3,Enrollment!A:A,1,FALSE) -> #N/A | C3: =VLOOKUP(A3,Building!A:A,1,FALSE) -> IU WAREHOUSE | D3: =VLOOKUP(A3,Distance!A:A,1,FALSE) -> IU WAREHOUSE
A4: 1114 INDIANA GARAGE | B4: =VLOOKUP(A4,Enrollment!A:A,1,FALSE) -> #N/A | C4: =VLOOKUP(A4,Building!A:A,1,FALSE) -> 1114 INDIANA GARAGE | D4: =VLOOKUP(A4,Distance!A:A,1,FALSE) -> 1114 INDIANA GARAGE
A5: MELLENCAMP PAVILION | B5: =VLOOKUP(A5,Enrollment!A:A,1,FALSE) -> #N/A | C5: =VLOOKUP(A5,Building!A:A,1,FALSE) -> MELLENCAMP PAVILION | D5: =VLOOKUP(A5,Distance!A:A,1,FALSE) -> MELLENCAMP PAVILION
A6: 1209 E MATLOCK RD | B6: =VLOOKUP(A6,Enrollment!A:A,1,FALSE) -> #N/A | C6: =VLOOKUP(A6,Building!A:A,1,FALSE) -> 1209 E MATLOCK RD | D6: =VLOOKUP(A6,Distance!A:A,1,FALSE) -> 1209 E MATLOCK RD
A7: DATA CENTER | B7: =VLOOKUP(A7,Enrollment!A:A,1,FALSE) -> #N/A | C7: =VLOOKUP(A7,Building!A:A,1,FALSE) -> DATA CENTER | D7: =VLOOKUP(A7,Distance!A:A,1,FALSE) -> DATA CENTER
A8: SIMON SKJODT ASSEMBLY HALL | B8: =VLOOKUP(A8,Enrollment!A:A,1,FALSE) -> SIMON SKJODT ASSEMBLY HALL | C8: =VLOOKUP(A8,Building!A:A,1,FALSE) -> SIMON SKJODT ASSEMBLY HALL | D8: =VLOOKUP(A8,Distance!A:A,1,FALSE) -> SIMON SKJODT ASSEMBLY HALL
A9: 711 E SR45/46 HOUSE | B9: =VLOOKUP(A9,Enrollment!A:A,1,FALSE) -> #N/A | C9: =VLOOKUP(A9,Building!A:A,1,FALSE) -> 711 E SR45/46 HOUSE | D9: =VLOOKUP(A9,Distance!A:A,1,FALSE) -> 711 E SR45/46 HOUSE
A10: 1020 N INDIANA AVE | B10: =VLOOKUP(A10,Enrollment!A:A,1,FALSE) -> #N/A | C10: =VLOOKUP(A10,Building!A:A,1,FALSE) -> 1020 N INDIANA AVE | D10: =VLOOKUP(A10,Distance!A:A,1,FALSE) -> 1020 N INDIANA AVE
A11: HAYES TRACK STORAGE | B11: =VLOOKUP(A11,Enrollment!A:A,1,FALSE) -> #N/A | C11: =VLOOKUP(A11,Building!A:A,1,FALSE) -> HAYES TRACK STORAGE | D11: =VLOOKUP(A11,Distance!A:A,1,FALSE) -> HAYES TRACK STORAGE
A12: POLE BARN B | B12: =VLOOKUP(A12,Enrollment!A:A,1,FALSE) -> #N/A | C12: =VLOOKUP(A12,Building!A:A,1,FALSE) -> POLE BARN B | D12: =VLOOKUP(A12,Distance!A:A,1,FALSE) -> POLE BARN B
A13: GLADSTEIN FIELDHOUSE | B13: =VLOOKUP(A13,Enrollment!A:A,1,FALSE) -> GLADSTEIN FIELDHOUSE | C13: =VLOOKUP(A13,Building!A:A,1,FALSE) -> GLADSTEIN FIELDHOUSE | D13: =VLOOKUP(A13,Distance!A:A,1,FALSE) -> GLADSTEIN FIELDHOUSE
... A354: 422 S GRANT GARAGE | B354: =VLOOKUP(A354,Enrollment!A:A,1,FALSE) -> #N/A | C354: =VLOOKUP(A354,Building!A:A,1,FALSE) -> 422 S GRANT GARAGE | D354: =VLOOKUP(A354,Distance!A:A,1,FALSE) -> 422 S GRANT GARAGE

Sheet new Sector
A1: Building
A2: MCNUTT CENTRAL
A3: IU STUDENT HEALTH CENTER
A4: ALPHA GAMMA DELTA
A5: IU WAREHOUSE
A6: 1114 INDIANA GARAGE
A7: MELLENCAMP PAVILION
A8: 1209 E MATLOCK RD
A9: DATA CENTER
A10: SIGMA ALPHA MU
A11: SIMON SKJODT ASSEMBLY HALL
A12: 711 E SR45/46 HOUSE
... A487: 422 S GRANT GARAGE

Sheet Sheet7
A1: LOT # | B1: Parking Space Inventory | D1: TITLE
A2: 102 | B2: Purple Lot-Stadium | C2: =TRIM(A2) -> 102 | D2: Atwater Parking Garage | F2: =VLOOKUP(C2,E7:E199,1,FALSE) -> 102
A3: 100 | B3: White Lot West of Stadium | C3: =TRIM(A3) -> 100 | D3: Fee Lane Parking Garage | F3: =VLOOKUP(C3,E8:E200,1,FALSE) -> #N/A
A4: 114 | B4: Green Lot-Tennis Pavillion | C4: =TRIM(A4) -> 114 | D4: Forrest Ave Parking Garage | F4: =VLOOKUP(C4,E9:E201,1,FALSE) -> 114
A5: 104 | B5: Orange Lot | C5: =TRIM(A5) -> 104 | D5: Headley School Parking | F5: =VLOOKUP(C5,E10:E202,1,FALSE) -> 104
A6: 442 | B6: Atwater Garage | C6: =TRIM(A6) -> 442 | D6: Henderson Parking Garage | F6: =VLOOKUP(C6,E11:E203,1,FALSE) -> #N/A
A7: 255 | B7: Fee Lane Garage | C7: =TRIM(A7) -> 255 | D7: Lot 100 | E7: =RIGHT(D7,3) -> 100 | F7: =VLOOKUP(C7,E12:E204,1,FALSE) -> #N/A
A8: 109 | B8: Blue Lot West West (Section E) | C8: =TRIM(A8) -> 109 | D8: Lot 102 | E8: =RIGHT(D8,3) -> 102 | F8: =VLOOKUP(C8,E13:E205,1,FALSE) -> #N/A
A9: 424 | B9: Henderson Garage and N. Annex | C9: =TRIM(A9) -> 424 | D9: Lot 102 | E9: =RIGHT(D9,3) -> 102 | F9: =VLOOKUP(C9,E14:E206,1,FALSE) -> #N/A
A10: 148 | B10: 10th St. at Sunrise (CH5) | C10: =TRIM(A10) -> 148 | D10: Lot 103 | E10: =RIGHT(D10,3) -> 103 | F10: =VLOOKUP(C10,E15:E207,1,FALSE) -> 148
A11: 515 | B11: Eigenmann-South (CH5) | C11: =TRIM(A11) -> 515 | D11: Lot 104 | E11: =RIGHT(D11,3) -> 104 | F11: =VLOOKUP(C11,E16:E208,1,FALSE) -> 515
A12: 400 | B12: Poplars Garage | C12: =TRIM(A12) -> 400 | D12: Lot 104 | E12: =RIGHT(D12,3) -> 104 | F12: =VLOOKUP(C12,E17:E209,1,FALSE) -> #N/A
A13: 238 | B13: Forrest Ave Garage-Luddy AI | C13: =TRIM(A13) -> 238 | D13: Lot 104 | E13: =RIGHT(D13,3) -> 104 | F13: =VLOOKUP(C13,E18:E210,1,FALSE) -> #N/A
A14: 226 | B14: 13th and Fee Lot | C14: =TRIM(A14) -> 226 | D14: Lot 104 | E14: =RIGHT(D14,3) -> 104 | F14: =VLOOKUP(C14,E19:E211,1,FALSE) -> 226
A15: 178 | B15: 2901 E Discovery Pkwy -SB (Service Bldg) | C15: =TRIM(A15) -> 178 | D15: Lot 104 | E15: =RIGHT(D15,3) -> 104 | F15: =VLOOKUP(C15,E20:E212,1,FALSE) -> 178
A16: 528 | B16: East Parking Garage-Upper | C16: =TRIM(A16) -> 528 | D16: Lot 108 | E16: =RIGHT(D16,3) -> 108 | F16: =VLOOKUP(C16,E21:E213,1,FALSE) -> #N/A
A17: 529 | B17: East Parging Garage-Lower | C17: =TRIM(A17) -> 529 | D17: Lot 110 | E17: =RIGHT(D17,3) -> 110 | F17: =VLOOKUP(C17,E22:E214,1,FALSE) -> 529
A18: 110 | B18: Blue Lot East (Section F) | C18: =TRIM(A18) -> 110 | D18: Lot 110 | E18: =RIGHT(D18,3) -> 110 | F18: =VLOOKUP(C18,E23:E215,1,FALSE) -> #N/A
... A201: 241 | B201: 600 - 700 Blk Walnut Grove | C201: =TRIM(A201) -> 241 | D201: Poplars Parking Garage | E201: =RIGHT(D201,3) -> age | F201: =VLOOKUP(C201,E206:E398,1,FALSE) -> #N/A
A202: 246 | B202: Walnut Grove Lot | C202: =TRIM(A202) -> 246 | E202: =RIGHT(D202,3) | F202: =VLOOKUP(C202,E207:E399,1,FALSE) -> #N/A
A203: 360 | B203: Radio/TV North Drive | C203: =TRIM(A203) -> 360 | E203: =RIGHT(D203,3) | F203: =VLOOKUP(C203,E208:E400,1,FALSE) -> #N/A
A204: 415 | B204: Sample Gate | C204: =TRIM(A204) -> 415 | E204: =RIGHT(D204,3) | F204: =VLOOKUP(C204,E209:E401,1,FALSE) -> #N/A
A205: 444 | B205: S Woodlawn/Simon H Access (Fire Drive) | C205: =TRIM(A205) -> 444 | E205: =RIGHT(D205,3) | F205: =VLOOKUP(C205,E210:E402,1,FALSE) -> #N/A
A206: 454 | B206: IMU S 700-1000 E Kirkwood | C206: =TRIM(A206) -> 454 | E206: =RIGHT(D206,3) | F206: =VLOOKUP(C206,E211:E403,1,FALSE) -> #N/A
A207: 462 | B207: Goodbody Hall-West | C207: =TRIM(A207) -> 462 | E207: =RIGHT(D207,3) | F207: =VLOOKUP(C207,E212:E404,1,FALSE) -> #N/A
A208: 502 | B208: 324 N. Eagleson | C208: =TRIM(A208) -> 502 | E208: =RIGHT(D208,3) | F208: =VLOOKUP(C208,E213:E405,1,FALSE) -> #N/A
A209: 506 | B209: Teter Circle | C209: =TRIM(A209) -> 506 | E209: =RIGHT(D209,3) | F209: =VLOOKUP(C209,E214:E406,1,FALSE) -> #N/A
A210: 516 | B210: Union Street | C210: =TRIM(A210) -> 516 | E210: =RIGHT(D210,3) | F210: =VLOOKUP(C210,E215:E407,1,FALSE) -> #N/A
A211: 551 | B211: Forest North-Dock | C211: =TRIM(A211) -> 551 | E211: =RIGHT(D211,3) | F211: =VLOOKUP(C211,E216:E408,1,FALSE) -> #N/A
A212: 559 | B212: Rose Ave. | C212: =TRIM(A212) -> 559 | E212: =RIGHT(D212,3) | F212: =VLOOKUP(C212,E217:E409,1,FALSE) -> #N/A
A213: 560 | B213: Willkie Circles | C213: =TRIM(A213) -> 560 | E213: =RIGHT(D213,3) | F213: =VLOOKUP(C213,E218:E410,1,FALSE) -> #N/A
... A221: 660 | B221: Hoosier Energy Site (Future) | C221: =TRIM(A221) -> 660 | E221: =RIGHT(D221,3) | F221: =VLOOKUP(C221,E226:E418,1,FALSE) -> #N/A

Sheet New_Enrollment
A1: building | B1: sector_mapping
A2: BALLANTINE HALL | B2: =VLOOKUP(A2,'new Sector'!A:A,1,FALSE) -> BALLANTINE HALL
A3: BLDG NOT ASSIGNED | B3: =VLOOKUP(A3,'new Sector'!A:A,1,FALSE) -> #N/A | C3: not required
A4: FRANKLIN HALL | B4: =VLOOKUP(A4,'new Sector'!A:A,1,FALSE) -> FRANKLIN HALL
A5: GLOBAL & INTL STUDIES BLDG | B5: =VLOOKUP(A5,'new Sector'!A:A,1,FALSE) -> GLOBAL & INTL STUDIES BLDG
A6: HODGE HALL (BUSINESS SCHOOL) | B6: =VLOOKUP(A6,'new Sector'!A:A,1,FALSE) -> HODGE HALL (BUSINESS SCHOOL)
A7: KIRKWOOD HALL | B7: =VLOOKUP(A7,'new Sector'!A:A,1,FALSE) -> KIRKWOOD HALL
A8: LEE NORVELLE THEATRE DRAMA/ NE | B8: =VLOOKUP(A8,'new Sector'!A:A,1,FALSE) -> #N/A
A9: LINDLEY HALL | B9: =VLOOKUP(A9,'new Sector'!A:A,1,FALSE) -> LINDLEY HALL
A10: LUDDY HALL (INFORMATICS) | B10: =VLOOKUP(A10,'new Sector'!A:A,1,FALSE) -> LUDDY HALL (INFORMATICS)
A11: PSYCHOLOGY | B11: =VLOOKUP(A11,'new Sector'!A:A,1,FALSE) -> PSYCHOLOGY
A12: SCHOOL OF PUBLIC HEALTH | B12: =VLOOKUP(A12,'new Sector'!A:A,1,FALSE) -> SCHOOL OF PUBLIC HEALTH
A13: SIMON MSC LBR REC | B13: =VLOOKUP(A13,'new Sector'!A:A,1,FALSE) -> SIMON MSC LBR REC
A14: SPEA | B14: =VLOOKUP(A14,'new Sector'!A:A,1,FALSE) -> SPEA
A15: SPRUCE HALL | B15: =VLOOKUP(A15,'new Sector'!A:A,1,FALSE) -> SPRUCE HALL
A16: STUDENT BUILDING (FRANCES MORG | B16: =VLOOKUP(A16,'new Sector'!A:A,1,FALSE) -> #N/A | C16: check
A17: WENDELL W. WRIGHT | B17: =VLOOKUP(A17,'new Sector'!A:A,1,FALSE) -> WENDELL W. WRIGHT
A18: WOODBURN HALL | B18: =VLOOKUP(A18,'new Sector'!A:A,1,FALSE) -> WOODBURN HALL
A19: WYLIE HALL | B19: =VLOOKUP(A19,'new Sector'!A:A,1,FALSE) -> WYLIE HALL
A20: \N | B20: =VLOOKUP(A20,'new Sector'!A:A,1,FALSE) -> #N/A | C20: check
A21: GODFREY GRAD&EXEC ED CTR | B21: =VLOOKUP(A21,'new Sector'!A:A,1,FALSE) -> GODFREY GRAD&EXEC ED CTR
A22: SIMON SKJODT ASSEMBLY HALL | B22: =VLOOKUP(A22,'new Sector'!A:A,1,FALSE) -> SIMON SKJODT ASSEMBLY HALL
A23: LOWELL E. BAIER HALL | B23: =VLOOKUP(A23,'new Sector'!A:A,1,FALSE) -> LOWELL E. BAIER HALL
A24: WEB-BASED CLASS | B24: =VLOOKUP(A24,'new Sector'!A:A,1,FALSE) -> #N/A | C24: not required
A25: 4TH & INDIANA-LEWIS BLDG | B25: =VLOOKUP(A25,'new Sector'!A:A,1,FALSE) -> 4TH & INDIANA-LEWIS BLDG
A26: AUDITORIUM | B26: =VLOOKUP(A26,'new Sector'!A:A,1,FALSE) -> AUDITORIUM
A27: BILL GARRETT FIELDHOUSE | B27: =VLOOKUP(A27,'new Sector'!A:A,1,FALSE) -> BILL GARRETT FIELDHOUSE
A28: BIOLOGY BUILDING | B28: =VLOOKUP(A28,'new Sector'!A:A,1,FALSE) -> BIOLOGY BUILDING
A29: BRISCOE QUAD | B29: =VLOOKUP(A29,'new Sector'!A:A,1,FALSE) -> BRISCOE QUAD
A30: CEDAR HALL | B30: =VLOOKUP(A30,'new Sector'!A:A,1,FALSE) -> CEDAR HALL
A31: CHEMISTRY | B31: =VLOOKUP(A31,'new Sector'!A:A,1,FALSE) -> CHEMISTRY
A32: CHEMISTRY ADDITION | B32: =VLOOKUP(A32,'new Sector'!A:A,1,FALSE) -> CHEMISTRY ADDITION
A33: CLASSROOM-OFFICE BUILDING | B33: =VLOOKUP(A33,'new Sector'!A:A,1,FALSE) -> CLASSROOM-OFFICE BUILDING
A34: EAST STUDIO BUILDING | B34: =VLOOKUP(A34,'new Sector'!A:A,1,FALSE) -> EAST STUDIO BUILDING
A35: EDMONDSON HALL | B35: =VLOOKUP(A35,'new Sector'!A:A,1,FALSE) -> EDMONDSON HALL
A36: ERNIE PYLE HALL | B36: =VLOOKUP(A36,'new Sector'!A:A,1,FALSE) -> ERNIE PYLE HALL
... A46: LUDDY CENTER FOR AI | B46: =VLOOKUP(A46,'new Sector'!A:A,1,FALSE) -> LUDDY CENTER FOR AI
A47: MARCHING HUNDRED HALL (RAY E C | B47: =VLOOKUP(A47,'new Sector'!A:A,1,FALSE) -> #N/A | C47: check
A48: MCNUTT CENTRAL | B48: =VLOOKUP(A48,'new Sector'!A:A,1,FALSE) -> MCNUTT CENTRAL
A49: MERRILL HALL | B49: =VLOOKUP(A49,'new Sector'!A:A,1,FALSE) -> MERRILL HALL
...
